what? std::exception
caught std::exception
